Workbook

Sheet Instrucoes
A1: CALCULADORA DE HONORARIOS CONTABEIS
A2: empreendedorweb.online - motor de calculo conforme NBC PG 01 e Res. CFC 1.590/2020
A5: COMO USAR
B6: 1. Aba Meu Escritorio | C6: Preencha o custo fixo mensal, as horas produtivas da equipe e a margem desejada. A planilha calcula o custo da sua hora e a sua hora tecnica. Faca isso UMA vez - vale para todos os clientes.
B7: 2. Aba Calculadora | C7: Preencha o perfil de UM cliente. O resultado mostra o piso de custo, o honorario recomendado e a composicao das horas.
B8: 3. Aba Carteira | C8: Lance ate 40 clientes de uma vez para ver quais estao abaixo do piso e quanto voce deixa de faturar.
B9: 4. Aba Parametros | C9: Ajuste as horas de cada regime, obrigacao e servico avulso conforme a realidade do seu escritorio.
A11: LEGENDA DE CORES
B12: Celula amarela / azul | C12: VOCE PREENCHE. Sao as unicas celulas que devem ser editadas.
B13: Texto preto | C13: Formula calculada automaticamente. Nao altere.
B14: Texto verde | C14: Valor puxado de outra aba da planilha.
A16: COMO O CALCULO FUNCIONA
B17: Custo da hora | C17: Custo fixo mensal / horas produtivas do mes. Quanto custa manter o escritorio aberto por uma hora.
B18: Hora tecnica | C18: Custo da hora x (1 + margem). E o valor que voce precisa cobrar por hora para ter lucro.
B19: Horas do cliente | C19: Soma das horas que aquele cliente consome: regime x atividade + folha + socios + volume fiscal + obrigacoes acessorias + filiais + porte.
B20: Piso de custo | C20: Horas do cliente x custo da hora. Cobrar abaixo disso e trabalhar no prejuizo.
B21: Honorario recomendado | C21: Horas do cliente x hora tecnica. E o valor sugerido para este perfil.
A23: BASE NORMATIVA E LIMITES
B24: Conselhos nao tabelam | C24: O Decreto-Lei 9.295/46 nao trata da mensuracao de honorarios e nao compete aos Conselhos fixar precos. As faixas de referencia de mercado nesta planilha sao sugestivas (sindicato/SESCON) e jamais obrigatorias - preco minimo imposto configuraria cartel.
B25: NBC PG 01 | C25: O Codigo de Etica determina que o honorario considere relevancia, vulto, complexidade, tempo e responsabilidade - exatamente os elementos calculados aqui. Veda a mercantilizacao e o aviltamento de honorarios.
B26: Res. CFC 1.590/2020 | C26: Exige contrato escrito discriminando o valor de cada servico prestado. Use o bloco Elementos da Proposta, na aba Calculadora, como base.
B27: Limite da ferramenta | C27: Esta planilha e instrumento de apoio a decisao. Nao substitui o julgamento profissional do contador nem a tabela do seu sindicato regional.
B29: Dica: | C29: Passe o mouse sobre as celulas com o triangulo vermelho no canto para ler a explicacao completa de cada campo.

Sheet Parametros
A1: PARAMETROS DO MOTOR DE CALCULO
A2: Ajuste estes valores conforme a realidade do seu escritorio - todas as abas usam esta pagina
B4: Todos os numeros abaixo sao referenciais e editaveis. Se a sua operacao gasta mais (ou menos) horas em algum item, altere aqui.
A6: REGIMES TRIBUTARIOS
B7: Regime | C7: Horas/mes | D7: Ref. min | E7: Ref. max
B8: MEI | C8: 0.6 | D8: 90 | E8: 180 | F8: Horas recorrentes de apuracao/escrituracao por mes.
B9: Simples Nacional | C9: 3 | D9: 350 | E9: 900 | F9: Ref. min/max = faixa sugestiva de mercado (sindicato).
B10: Lucro Presumido | C10: 6.5 | D10: 700 | E10: 2200 | F10: NAO e tabela obrigatoria - ver aba Instrucoes.
B11: Lucro Real | C11: 14 | D11: 1800 | E11: 7000
A13: ATIVIDADE ECONOMICA
B14: Atividade | C14: Multiplicador
B15: Comercio | C15: 1 | F15: Multiplica as horas do regime. Industria pesa mais por IPI,
B16: Servicos | C16: 1.05 | F16: controle de producao, custos e estoque.
B17: Industria | C17: 1.35
A19: VOLUME DE DOCUMENTOS FISCAIS
B20: Faixa | C20: Horas/mes
B21: Ate 20 NF/mes | C21: 0 | F21: Horas adicionais de escrituracao e conciliacao.
B22: 21 a 80 NF/mes | C22: 1.5
B23: 81 a 200 NF/mes | C23: 4
B24: 201 a 500 NF/mes | C24: 8
B25: Acima de 500 NF/mes | C25: 14
A27: OBRIGACOES ACESSORIAS ADICIONAIS
B28: Obrigacao | C28: Horas/mes
B29: EFD-Contribuicoes | C29: 1.5 | F29: Contam apenas quando marcadas para o cliente.
B30: EFD-Reinf | C30: 1.2
B31: ECD (Sped Contabil) | C31: 1.5
B32: ECF | C32: 1.5
B33: DCTFWeb | C33: 0.8
B34: ICMS-ST / DIFAL | C34: 1.5
B35: Comercio exterior (Imp/Exp) | C35: 2.5
A37: PESOS UNITARIOS
B38: Horas por funcionario (CLT) | C38: 0.45 | F38: Folha, eSocial, FGTS, ferias, 13o, rescisao.
B39: Horas por socio | C39: 0.35 | F39: Pro-labore, INSS, distribuicao de lucros.
B40: Horas por filial / IE adicional | C40: 1.5 | F40: Apuracao e obrigacoes estaduais separadas.
A42: AJUSTE POR PORTE (FATURAMENTO MENSAL)
B43: Faturamento ate | C43: Horas/mes
B44: 80000 | C44: 0 | F44: Faturamento maior = mais movimento e responsabilidade.
B45: 300000 | C45: 0.8 | F45: Busca a PRIMEIRA faixa cujo limite seja >= o faturamento.
B46: 1000000 | C46: 2
B47: 1000000000000 | C47: 4
...

Sheet Meu Escritorio
A1: MEU ESCRITORIO
A2: Descubra quanto custa a sua hora - preencha uma vez, vale para todos os clientes
A4: CUSTOS E CAPACIDADE
B5: Custo fixo mensal do escritorio | C5: 28000 | E5: Salarios, encargos, pro-labore, aluguel, softwares, certificado digital.
B6: Horas produtivas da equipe por mes | C6: 320 | E6: Somente horas faturaveis. Ex.: 2 pessoas x 160h = 320h.
B7: Margem de lucro desejada | C7: 0.3 | E7: Sobre o custo da hora. No setor, entre 20% e 40%.
A9: RESULTADO - SUA HORA
B10: Custo da sua hora | C10: =IF(C6=0,0,C5/C6) -> 87.5 | E10: Custo fixo / horas produtivas. Abaixo disso, prejuizo.
B11: SUA HORA TECNICA | C11: =C10*(1+C7) -> 113.75 | E11: Custo da hora + margem. E o valor que sustenta o escritorio.
B13: Custo anual do escritorio | C13: =C5*12 -> 336000
B14: Faturamento anual necessario | C14: =C11*C6*12 -> 436800 | E14: Se toda a capacidade produtiva fosse vendida a hora tecnica.
B16: Atencao: | E16: Se as horas produtivas estiverem superestimadas, o custo da hora sai baixo demais e todo o resto do calculo fica subdimensionado.
B19: Ferramenta de apoio a decisao. Os Conselhos de Contabilidade nao tabelam honorarios - os valores sao definidos por voce. Nao substitui o julgamento profissional nem a tabela do sindicato regional.

Sheet Calculadora
A1: CALCULADORA DE HONORARIOS - CLIENTE
A2: Preencha o perfil do cliente nas celulas amarelas
A4: IDENTIFICACAO
B5: Nome do cliente | C5: Exemplo Comercio Ltda | F5: Linha de exemplo - substitua pelos dados reais.
A7: PERFIL DO CLIENTE
B8: Regime tributario | C8: Simples Nacional | F8: Maior fator de complexidade do calculo.
B9: Atividade economica | C9: Servicos
B10: Faturamento mensal medio | C10: 50000 | F10: Media dos ultimos 12 meses.
B11: Funcionarios (CLT) | C11: 2 | F11: Nao inclua socios aqui.
B12: Socios | C12: 1
B13: Filiais / IE adicionais | C13: 0
B14: Volume de documentos fiscais | C14: 21 a 80 NF/mes | F14: Entradas + saidas por mes.
A16: OBRIGACOES ACESSORIAS ADICIONAIS (marque X)
B17: Obrigacao | C17: Marcar (X) | D17: Horas
B18: =Parametros!B29 -> EFD-Contribuicoes | D18: =IF(UPPER(C18)="X",Parametros!$C$29,0) -> 0
B19: =Parametros!B30 -> EFD-Reinf | D19: =IF(UPPER(C19)="X",Parametros!$C$30,0) -> 0
B20: =Parametros!B31 -> ECD (Sped Contabil) | D20: =IF(UPPER(C20)="X",Parametros!$C$31,0) -> 0
B21: =Parametros!B32 -> ECF | D21: =IF(UPPER(C21)="X",Parametros!$C$32,0) -> 0
B22: =Parametros!B33 -> DCTFWeb | D22: =IF(UPPER(C22)="X",Parametros!$C$33,0) -> 0
B23: =Parametros!B34 -> ICMS-ST / DIFAL | D23: =IF(UPPER(C23)="X",Parametros!$C$34,0) -> 0
B24: =Parametros!B35 -> Comercio exterior (Imp/Exp) | D24: =IF(UPPER(C24)="X",Parametros!$C$35,0) -> 0
A26: COMPOSICAO DAS HORAS MENSAIS
B27: Componente | C27: Horas/mes | D27: Valor
B28: Regime x atividade | C28: =IFERROR(INDEX(Parametros!$C$8:$C$11,MATCH($C$8,Parametros!$B$8:$B$11,0))*INDEX(Parametros!$C$15:$C$17,MATCH($C$9,Parametros!$B$15:$B$17,0)),0) -> 3.15 | D28: =C28*'Meu Escritorio'!$C$11 -> 358.3125
B29: Folha / departamento pessoal | C29: =$C$11*Parametros!$C$38 -> 0.9 | D29: =C29*'Meu Escritorio'!$C$11 -> 102.375
B30: Socios / pro-labore | C30: =$C$12*Parametros!$C$39 -> 0.35 | D30: =C30*'Meu Escritorio'!$C$11 -> 39.8125
B31: Volume fiscal | C31: =IFERROR(INDEX(Parametros!$C$21:$C$25,MATCH($C$14,Parametros!$B$21:$B$25,0)),0) -> 1.5 | D31: =C31*'Meu Escritorio'!$C$11 -> 170.625
B32: Obrigacoes acessorias | C32: =SUM(D18:D24) -> 0 | D32: =C32*'Meu Escritorio'!$C$11 -> 0
B33: Filiais / IE adicionais | C33: =$C$13*Parametros!$C$40 -> 0 | D33: =C33*'Meu Escritorio'!$C$11 -> 0
B34: Porte / movimento | C34: =IFERROR(INDEX(Parametros!$C$44:$C$47,MATCH(TRUE(),INDEX(Parametros!$B$44:$B$47>=$C$10,0),0)),0) -> 0 | D34: =C34*'Meu Escritorio'!$C$11 -> 0
B35: TOTAL | C35: =SUM(C28:C34) -> 5.9 | D35: =SUM(D28:D34) -> 671.125
A37: RESULTADO
B38: Piso de custo (nao cobrar abaixo) | C38: =C35*'Meu Escritorio'!$C$10 -> 516.25 | F38: Horas do cliente x custo da sua hora. Abaixo disso = prejuizo.
B39: HONORARIO MENSAL RECOMENDADO | C39: =C35*'Meu Escritorio'!$C$11 -> 671.125 | F39: Horas do cliente x sua hora tecnica.
B40: Honorario anual | C40: =C39*12 -> 8053.5
B41: Referencia de mercado (sugestiva) | C41: =IFERROR(TEXT(INDEX(Parametros!$D$8:$D$11,MATCH($C$8,Parametros!$B$8:$B$11,0)),"R$ #,##0")&" a "&TEXT(INDEX(Parametros!$E$8:$E$11,MATCH($C$8,Parametros!$B$8:$B$11,0)),"R$ #,##0"),"-") -> R$ 350 a R$ 900 | F41: Faixa de sindicato/SESCON. Sugestiva - nunca obrigatoria.
A43: CHECAGEM DO SEU PRECO
B44: Quanto voce pretende cobrar? | C44: 0
B45: Diagnostico | C45: =IF(C44<=0,"Preencha o valor pretendido acima",IF(C44<C38,"ABAIXO DO PISO - risco de aviltamento (NBC PG 01)",IF(C44<C39*0.92,"Cobre o custo, mas comprime a sua margem",IF(C44>C39*1.15,"Acima do recomendado - exige valor percebido","Dentro da faixa recomendada")))) -> Preencha o valor pretendido acima
B46: Diferenca para o recomendado | C46: =IF(C44<=0,0,C44-C39) -> 0
...

Sheet Carteira
A1: CARTEIRA DE CLIENTES
A2: Lance todos os seus clientes e descubra quais estao abaixo do piso de custo
B4: Preencha as colunas amarelas. Na coluna Obrigacoes, informe QUANTAS obrigacoes acessorias adicionais o cliente tem (a planilha usa a media de horas das obrigacoes cadastradas).
B6: Cliente | C6: Regime | D6: Atividade | E6: Faturamento | F6: Func. | G6: Socios | H6: Filiais | I6: Volume fiscal | J6: Obrig. | K6: Horas/mes | L6: Piso | M6: Recomendado | N6: Cobra hoje | O6: Situacao
B7: Exemplo Comercio Ltda | C7: Simples Nacional | D7: Comercio | E7: 50000 | F7: 2 | G7: 1 | H7: 0 | I7: 21 a 80 NF/mes | J7: 2 | K7: =IF($B7="","",IFERROR(INDEX(Parametros!$C$8:$C$11,MATCH($C7,Parametros!$B$8:$B$11,0))*INDEX(Parametros!$C$15:$C$17,MATCH($D7,Parametros!$B$15:$B$17,0)),0)+$F7*Parametros!$C$38+$G7*Parametros!$C$39+$H7*Parametros!$C$40+IFERROR(INDEX(Parametros!$C$21:$C$25,MATCH($I7,Parametros!$B$21:$B$25,0)),0)+$J7*AVERAGE(Parametros!$C$29:$C$35)+IFERROR(INDEX(Parametros!$C$44:$C$47,MATCH(TRUE(),INDEX(Parametros!$B$44:$B$47>=$E7,0),0)),0)) -> 8.75 | L7: =IF($B7="","",K7*'Meu Escritorio'!$C$10) -> 765.625 | M7: =IF($B7="","",K7*'Meu Escritorio'!$C$11) -> 995.3125 | N7: 900 | O7: =IF($B7="","",IF(N7<=0,"Informe o valor cobrado",IF(N7<L7,"ABAIXO DO PISO - prejuizo",IF(N7<M7*0.92,"Margem comprimida",IF(N7>M7*1.15,"Acima do recomendado","Adequado"))))) -> Margem comprimida
K8: =IF($B8="","",IFERROR(INDEX(Parametros!$C$8:$C$11,MATCH($C8,Parametros!$B$8:$B$11,0))*INDEX(Parametros!$C$15:$C$17,MATCH($D8,Parametros!$B$15:$B$17,0)),0)+$F8*Parametros!$C$38+$G8*Parametros!$C$39+$H8*Parametros!$C$40+IFERROR(INDEX(Parametros!$C$21:$C$25,MATCH($I8,Parametros!$B$21:$B$25,0)),0)+$J8*AVERAGE(Parametros!$C$29:$C$35)+IFERROR(INDEX(Parametros!$C$44:$C$47,MATCH(TRUE(),INDEX(Parametros!$B$44:$B$47>=$E8,0),0)),0)) | L8: =IF($B8="","",K8*'Meu Escritorio'!$C$10) | M8: =IF($B8="","",K8*'Meu Escritorio'!$C$11) | O8: =IF($B8="","",IF(N8<=0,"Informe o valor cobrado",IF(N8<L8,"ABAIXO DO PISO - prejuizo",IF(N8<M8*0.92,"Margem comprimida",IF(N8>M8*1.15,"Acima do recomendado","Adequado")))))
K9: =IF($B9="","",IFERROR(INDEX(Parametros!$C$8:$C$11,MATCH($C9,Parametros!$B$8:$B$11,0))*INDEX(Parametros!$C$15:$C$17,MATCH($D9,Parametros!$B$15:$B$17,0)),0)+$F9*Parametros!$C$38+$G9*Parametros!$C$39+$H9*Parametros!$C$40+IFERROR(INDEX(Parametros!$C$21:$C$25,MATCH($I9,Parametros!$B$21:$B$25,0)),0)+$J9*AVERAGE(Parametros!$C$29:$C$35)+IFERROR(INDEX(Parametros!$C$44:$C$47,MATCH(TRUE(),INDEX(Parametros!$B$44:$B$47>=$E9,0),0)),0)) | L9: =IF($B9="","",K9*'Meu Escritorio'!$C$10) | M9: =IF($B9="","",K9*'Meu Escritorio'!$C$11) | O9: =IF($B9="","",IF(N9<=0,"Informe o valor cobrado",IF(N9<L9,"ABAIXO DO PISO - prejuizo",IF(N9<M9*0.92,"Margem comprimida",IF(N9>M9*1.15,"Acima do recomendado","Adequado")))))
K10: =IF($B10="","",IFERROR(INDEX(Parametros!$C$8:$C$11,MATCH($C10,Parametros!$B$8:$B$11,0))*INDEX(Parametros!$C$15:$C$17,MATCH($D10,Parametros!$B$15:$B$17,0)),0)+$F10*Parametros!$C$38+$G10*Parametros!$C$39+$H10*Parametros!$C$40+IFERROR(INDEX(Parametros!$C$21:$C$25,MATCH($I10,Parametros!$B$21:$B$25,0)),0)+$J10*AVERAGE(Parametros!$C$29:$C$35)+IFERROR(INDEX(Parametros!$C$44:$C$47,MATCH(TRUE(),INDEX(Parametros!$B$44:$B$47>=$E10,0),0)),0)) | L10: =IF($B10="","",K10*'Meu Escritorio'!$C$10) | M10: =IF($B10="","",K10*'Meu Escritorio'!$C$11) | O10: =IF($B10="","",IF(N10<=0,"Informe o valor cobrado",IF(N10<L10,"ABAIXO DO PISO - prejuizo",IF(N10<M10*0.92,"Margem comprimida",IF(N10>M10*1.15,"Acima do recomendado","Adequado")))))
K11: =IF($B11="","",IFERROR(INDEX(Parametros!$C$8:$C$11,MATCH($C11,Parametros!$B$8:$B$11,0))*INDEX(Parametros!$C$15:$C$17,MATCH($D11,Parametros!$B$15:$B$17,0)),0)+$F11*Parametros!$C$38+$G11*Parametros!$C$39+$H11*Parametros!$C$40+IFERROR(INDEX(Parametros!$C$21:$C$25,MATCH($I11,Parametros!$B$21:$B$25,0)),0)+$J11*AVERAGE(Parametros!$C$29:$C$35)+IFERROR(INDEX(Parametros!$C$44:$C$47,MATCH(TRUE(),INDEX(Parametros!$B$44:$B$47>=$E11,0),0)),0)) | L11: =IF($B11="","",K11*'Meu Escritorio'!$C$10) | M11: =IF($B11="","",K11*'Meu Escritorio'!$C$11) | O11: =IF($B11="","",IF(N11<=0,"Informe o valor cobrado",IF(N11<L11,"ABAIXO DO PISO - prejuizo",IF(N11<M11*0.92,"Margem comprimida",IF(N11>M11*1.15,"Acima do recomendado","Adequado")))))
K12: =IF($B12="","",IFERROR(INDEX(Parametros!$C$8:$C$11,MATCH($C12,Parametros!$B$8:$B$11,0))*INDEX(Parametros!$C$15:$C$17,MATCH($D12,Parametros!$B$15:$B$17,0)),0)+$F12*Parametros!$C$38+$G12*Parametros!$C$39+$H12*Parametros!$C$40+IFERROR(INDEX(Parametros!$C$21:$C$25,MATCH($I12,Parametros!$B$21:$B$25,0)),0)+$J12*AVERAGE(Parametros!$C$29:$C$35)+IFERROR(INDEX(Parametros!$C$44:$C$47,MATCH(TRUE(),INDEX(Parametros!$B$44:$B$47>=$E12,0),0)),0)) | L12: =IF($B12="","",K12*'Meu Escritorio'!$C$10) | M12: =IF($B12="","",K12*'Meu Escritorio'!$C$11) | O12: =IF($B12="","",IF(N12<=0,"Informe o valor cobrado",IF(N12<L12,"ABAIXO DO PISO - prejuizo",IF(N12<M12*0.92,"Margem comprimida",IF(N12>M12*1.15,"Acima do recomendado","Adequado")))))
K13: =IF($B13="","",IFERROR(INDEX(Parametros!$C$8:$C$11,MATCH($C13,Parametros!$B$8:$B$11,0))*INDEX(Parametros!$C$15:$C$17,MATCH($D13,Parametros!$B$15:$B$17,0)),0)+$F13*Parametros!$C$38+$G13*Parametros!$C$39+$H13*Parametros!$C$40+IFERROR(INDEX(Parametros!$C$21:$C$25,MATCH($I13,Parametros!$B$21:$B$25,0)),0)+$J13*AVERAGE(Parametros!$C$29:$C$35)+IFERROR(INDEX(Parametros!$C$44:$C$47,MATCH(TRUE(),INDEX(Parametros!$B$44:$B$47>=$E13,0),0)),0)) | L13: =IF($B13="","",K13*'Meu Escritorio'!$C$10) | M13: =IF($B13="","",K13*'Meu Escritorio'!$C$11) | O13: =IF($B13="","",IF(N13<=0,"Informe o valor cobrado",IF(N13<L13,"ABAIXO DO PISO - prejuizo",IF(N13<M13*0.92,"Margem comprimida",IF(N13>M13*1.15,"Acima do recomendado","Adequado")))))
K14: =IF($B14="","",IFERROR(INDEX(Parametros!$C$8:$C$11,MATCH($C14,Parametros!$B$8:$B$11,0))*INDEX(Parametros!$C$15:$C$17,MATCH($D14,Parametros!$B$15:$B$17,0)),0)+$F14*Parametros!$C$38+$G14*Parametros!$C$39+$H14*Parametros!$C$40+IFERROR(INDEX(Parametros!$C$21:$C$25,MATCH($I14,Parametros!$B$21:$B$25,0)),0)+$J14*AVERAGE(Parametros!$C$29:$C$35)+IFERROR(INDEX(Parametros!$C$44:$C$47,MATCH(TRUE(),INDEX(Parametros!$B$44:$B$47>=$E14,0),0)),0)) | L14: =IF($B14="","",K14*'Meu Escritorio'!$C$10) | M14: =IF($B14="","",K14*'Meu Escritorio'!$C$11) | O14: =IF($B14="","",IF(N14<=0,"Informe o valor cobrado",IF(N14<L14,"ABAIXO DO PISO - prejuizo",IF(N14<M14*0.92,"Margem comprimida",IF(N14>M14*1.15,"Acima do recomendado","Adequado")))))
K15: =IF($B15="","",IFERROR(INDEX(Parametros!$C$8:$C$11,MATCH($C15,Parametros!$B$8:$B$11,0))*INDEX(Parametros!$C$15:$C$17,MATCH($D15,Parametros!$B$15:$B$17,0)),0)+$F15*Parametros!$C$38+$G15*Parametros!$C$39+$H15*Parametros!$C$40+IFERROR(INDEX(Parametros!$C$21:$C$25,MATCH($I15,Parametros!$B$21:$B$25,0)),0)+$J15*AVERAGE(Parametros!$C$29:$C$35)+IFERROR(INDEX(Parametros!$C$44:$C$47,MATCH(TRUE(),INDEX(Parametros!$B$44:$B$47>=$E15,0),0)),0)) | L15: =IF($B15="","",K15*'Meu Escritorio'!$C$10) | M15: =IF($B15="","",K15*'Meu Escritorio'!$C$11) | O15: =IF($B15="","",IF(N15<=0,"Informe o valor cobrado",IF(N15<L15,"ABAIXO DO PISO - prejuizo",IF(N15<M15*0.92,"Margem comprimida",IF(N15>M15*1.15,"Acima do recomendado","Adequado")))))
K16: =IF($B16="","",IFERROR(INDEX(Parametros!$C$8:$C$11,MATCH($C16,Parametros!$B$8:$B$11,0))*INDEX(Parametros!$C$15:$C$17,MATCH($D16,Parametros!$B$15:$B$17,0)),0)+$F16*Parametros!$C$38+$G16*Parametros!$C$39+$H16*Parametros!$C$40+IFERROR(INDEX(Parametros!$C$21:$C$25,MATCH($I16,Parametros!$B$21:$B$25,0)),0)+$J16*AVERAGE(Parametros!$C$29:$C$35)+IFERROR(INDEX(Parametros!$C$44:$C$47,MATCH(TRUE(),INDEX(Parametros!$B$44:$B$47>=$E16,0),0)),0)) | L16: =IF($B16="","",K16*'Meu Escritorio'!$C$10) | M16: =IF($B16="","",K16*'Meu Escritorio'!$C$11) | O16: =IF($B16="","",IF(N16<=0,"Informe o valor cobrado",IF(N16<L16,"ABAIXO DO PISO - prejuizo",IF(N16<M16*0.92,"Margem comprimida",IF(N16>M16*1.15,"Acima do recomendado","Adequado")))))
K17: =IF($B17="","",IFERROR(INDEX(Parametros!$C$8:$C$11,MATCH($C17,Parametros!$B$8:$B$11,0))*INDEX(Parametros!$C$15:$C$17,MATCH($D17,Parametros!$B$15:$B$17,0)),0)+$F17*Parametros!$C$38+$G17*Parametros!$C$39+$H17*Parametros!$C$40+IFERROR(INDEX(Parametros!$C$21:$C$25,MATCH($I17,Parametros!$B$21:$B$25,0)),0)+$J17*AVERAGE(Parametros!$C$29:$C$35)+IFERROR(INDEX(Parametros!$C$44:$C$47,MATCH(TRUE(),INDEX(Parametros!$B$44:$B$47>=$E17,0),0)),0)) | L17: =IF($B17="","",K17*'Meu Escritorio'!$C$10) | M17: =IF($B17="","",K17*'Meu Escritorio'!$C$11) | O17: =IF($B17="","",IF(N17<=0,"Informe o valor cobrado",IF(N17<L17,"ABAIXO DO PISO - prejuizo",IF(N17<M17*0.92,"Margem comprimida",IF(N17>M17*1.15,"Acima do recomendado","Adequado")))))
K18: =IF($B18="","",IFERROR(INDEX(Parametros!$C$8:$C$11,MATCH($C18,Parametros!$B$8:$B$11,0))*INDEX(Parametros!$C$15:$C$17,MATCH($D18,Parametros!$B$15:$B$17,0)),0)+$F18*Parametros!$C$38+$G18*Parametros!$C$39+$H18*Parametros!$C$40+IFERROR(INDEX(Parametros!$C$21:$C$25,MATCH($I18,Parametros!$B$21:$B$25,0)),0)+$J18*AVERAGE(Parametros!$C$29:$C$35)+IFERROR(INDEX(Parametros!$C$44:$C$47,MATCH(TRUE(),INDEX(Parametros!$B$44:$B$47>=$E18,0),0)),0)) | L18: =IF($B18="","",K18*'Meu Escritorio'!$C$10) | M18: =IF($B18="","",K18*'Meu Escritorio'!$C$11) | O18: =IF($B18="","",IF(N18<=0,"Informe o valor cobrado",IF(N18<L18,"ABAIXO DO PISO - prejuizo",IF(N18<M18*0.92,"Margem comprimida",IF(N18>M18*1.15,"Acima do recomendado","Adequado")))))
K19: =IF($B19="","",IFERROR(INDEX(Parametros!$C$8:$C$11,MATCH($C19,Parametros!$B$8:$B$11,0))*INDEX(Parametros!$C$15:$C$17,MATCH($D19,Parametros!$B$15:$B$17,0)),0)+$F19*Parametros!$C$38+$G19*Parametros!$C$39+$H19*Parametros!$C$40+IFERROR(INDEX(Parametros!$C$21:$C$25,MATCH($I19,Parametros!$B$21:$B$25,0)),0)+$J19*AVERAGE(Parametros!$C$29:$C$35)+IFERROR(INDEX(Parametros!$C$44:$C$47,MATCH(TRUE(),INDEX(Parametros!$B$44:$B$47>=$E19,0),0)),0)) | L19: =IF($B19="","",K19*'Meu Escritorio'!$C$10) | M19: =IF($B19="","",K19*'Meu Escritorio'!$C$11) | O19: =IF($B19="","",IF(N19<=0,"Informe o valor cobrado",IF(N19<L19,"ABAIXO DO PISO - prejuizo",IF(N19<M19*0.92,"Margem comprimida",IF(N19>M19*1.15,"Acima do recomendado","Adequado")))))
... K46: =IF($B46="","",IFERROR(INDEX(Parametros!$C$8:$C$11,MATCH($C46,Parametros!$B$8:$B$11,0))*INDEX(Parametros!$C$15:$C$17,MATCH($D46,Parametros!$B$15:$B$17,0)),0)+$F46*Parametros!$C$38+$G46*Parametros!$C$39+$H46*Parametros!$C$40+IFERROR(INDEX(Parametros!$C$21:$C$25,MATCH($I46,Parametros!$B$21:$B$25,0)),0)+$J46*AVERAGE(Parametros!$C$29:$C$35)+IFERROR(INDEX(Parametros!$C$44:$C$47,MATCH(TRUE(),INDEX(Parametros!$B$44:$B$47>=$E46,0),0)),0)) | L46: =IF($B46="","",K46*'Meu Escritorio'!$C$10) | M46: =IF($B46="","",K46*'Meu Escritorio'!$C$11) | O46: =IF($B46="","",IF(N46<=0,"Informe o valor cobrado",IF(N46<L46,"ABAIXO DO PISO - prejuizo",IF(N46<M46*0.92,"Margem comprimida",IF(N46>M46*1.15,"Acima do recomendado","Adequado")))))
B48: TOTAIS DA CARTEIRA | K48: =SUM(K7:K46) -> 8.75 | L48: =SUM(L7:L46) -> 765.625 | M48: =SUM(M7:M46) -> 995.3125 | N48: =SUM(N7:N46) -> 900
A50: DIAGNOSTICO DA CARTEIRA
B51: Clientes lancados | C51: =COUNTIF(B7:B46,"?*") -> 1 | E51: Valores negativos em 'Diferenca' indicam quanto voce deixa de faturar na carteira inteira.
B52: Clientes abaixo do piso de custo | C52: =COUNTIF(O7:O46,"ABAIXO DO PISO*") -> 0 | E52: Ocupacao acima de 100% significa que a demanda ja excede a capacidade produtiva informada.
B53: Clientes com margem comprimida | C53: =COUNTIF(O7:O46,"Margem comprimida") -> 1
B54: Clientes adequados | C54: =COUNTIF(O7:O46,"Adequado")+COUNTIF(O7:O46,"Acima do recomendado") -> 0
B55: Faturamento mensal atual | C55: =SUM(N7:N46) -> 900
B56: Faturamento mensal recomendado | C56: =SUM(M7:M46) -> 995.3125
B57: Diferenca por mes | C57: =N48-M48 -> -95.3125
B58: Diferenca por ano | C58: =(N48-M48)*12 -> -1143.75
B59: Ocupacao da capacidade da equipe | C59: =IF('Meu Escritorio'!$C$6=0,0,K48/'Meu Escritorio'!$C$6) -> 0.02734375
B62: Ferramenta de apoio a decisao. Os Conselhos de Contabilidade nao tabelam honorarios - os valores sao definidos por voce. Nao substitui o julgamento profissional nem a tabela do sindicato regional.
